<?xml version="1.0" encoding="UTF-8"?>
<!-- Generated by org.testng.reporters.JUnitXMLReporter -->
<testsuite hostname="DESKTOP-MJ9OJ63" ignored="0" name="G8S1LV05133401MM" tests="12" failures="3" timestamp="2022-07-02T11:48:05 ICT" time="50.843" errors="0">
  <testcase name="@AfterMethod captureScreenshot" time="0.381" classname="test.BaseTest">
    <failure type="java.lang.RuntimeException" message="Unable to create a new remote session. Please check the server log for more details. Original error: An unknown server-side error occurred while processing the command. Original error: Device 3300d3672cca62b9 was not in the list of connected devices
Build info: version: &amp;apos;unknown&amp;apos;, revision: &amp;apos;unknown&amp;apos;, time: &amp;apos;unknown&amp;apos;
System info: host: &amp;apos;DESKTOP-MJ9OJ63&amp;apos;, ip: &amp;apos;192.168.1.46&amp;apos;, os.name: &amp;apos;Windows 10&amp;apos;, os.arch: &amp;apos;amd64&amp;apos;, os.version: &amp;apos;10.0&amp;apos;, java.version: &amp;apos;1.8.0_321&amp;apos;
Driver info: driver.version: AndroidDriver
remote stacktrace: UnknownError: An unknown server-side error occurred while processing the command. Original error: Device 3300d3672cca62b9 was not in the list of connected devices
    at getResponseForW3CError (C:\Users\Admin\AppData\Roaming\npm\node_modules\appium\node_modules\appium-base-driver\lib\protocol\errors.js:804:9)
    at asyncHandler (C:\Users\Admin\AppData\Roaming\npm\node_modules\appium\node_modules\appium-base-driver\lib\protocol\protocol.js:380:37)
Build info: version: &amp;apos;unknown&amp;apos;, revision: &amp;apos;unknown&amp;apos;, time: &amp;apos;unknown&amp;apos;
System info: host: &amp;apos;DESKTOP-MJ9OJ63&amp;apos;, ip: &amp;apos;192.168.1.46&amp;apos;, os.name: &amp;apos;Windows 10&amp;apos;, os.arch: &amp;apos;amd64&amp;apos;, os.version: &amp;apos;10.0&amp;apos;, java.version: &amp;apos;1.8.0_321&amp;apos;
Driver info: driver.version: AndroidDriver">
      <![CDATA[java.lang.RuntimeException: Unable to create a new remote session. Please check the server log for more details. Original error: An unknown server-side error occurred while processing the command. Original error: Device 3300d3672cca62b9 was not in the list of connected devices
Build info: version: 'unknown', revision: 'unknown', time: 'unknown'
System info: host: 'DESKTOP-MJ9OJ63', ip: '192.168.1.46', os.name: 'Windows 10', os.arch: 'amd64', os.version: '10.0', java.version: '1.8.0_321'
Driver info: driver.version: AndroidDriver
remote stacktrace: UnknownError: An unknown server-side error occurred while processing the command. Original error: Device 3300d3672cca62b9 was not in the list of connected devices
    at getResponseForW3CError (C:\Users\Admin\AppData\Roaming\npm\node_modules\appium\node_modules\appium-base-driver\lib\protocol\errors.js:804:9)
    at asyncHandler (C:\Users\Admin\AppData\Roaming\npm\node_modules\appium\node_modules\appium-base-driver\lib\protocol\protocol.js:380:37)
Build info: version: 'unknown', revision: 'unknown', time: 'unknown'
System info: host: 'DESKTOP-MJ9OJ63', ip: '192.168.1.46', os.name: 'Windows 10', os.arch: 'amd64', os.version: '10.0', java.version: '1.8.0_321'
Driver info: driver.version: AndroidDriver
at driver.DriverFactory.getDriver(DriverFactory.java:93)
at test.BaseTest.captureScreenshot(BaseTest.java:76)
at java.util.ArrayList.forEach(Unknown Source)
at java.util.concurrent.FutureTask.run(Unknown Source)
at java.util.concurrent.ThreadPoolExecutor.runWorker(Unknown Source)
at java.util.concurrent.ThreadPoolExecutor$Worker.run(Unknown Source)
at java.lang.Thread.run(Unknown Source)
... Removed 23 stack frames]]>
    </failure>
  </testcase> <!-- @AfterMethod captureScreenshot -->
  <testcase name="@AfterMethod captureScreenshot" time="0.0" classname="test.BaseTest">
    <skipped/>
  </testcase> <!-- @AfterMethod captureScreenshot -->
  <testcase name="@AfterMethod captureScreenshot" time="0.0" classname="test.BaseTest">
    <skipped/>
  </testcase> <!-- @AfterMethod captureScreenshot -->
  <testcase name="@AfterMethod captureScreenshot" time="0.001" classname="test.BaseTest">
    <failure type="java.lang.NullPointerException" message="Name is null">
      <![CDATA[java.lang.NullPointerException: Name is null
at java.lang.Enum.valueOf(Unknown Source)
at driver.Platforms.valueOf(Platforms.java:3)
at test.BaseTest.captureScreenshot(BaseTest.java:76)
at java.util.ArrayList.forEach(Unknown Source)
at java.util.concurrent.FutureTask.run(Unknown Source)
at java.util.concurrent.ThreadPoolExecutor.runWorker(Unknown Source)
at java.util.concurrent.ThreadPoolExecutor$Worker.run(Unknown Source)
at java.lang.Thread.run(Unknown Source)
... Removed 23 stack frames]]>
    </failure>
  </testcase> <!-- @AfterMethod captureScreenshot -->
  <testcase name="testLogin" time="26.414" classname="learning.lesson_19.LoginTest"/>
  <testcase name="testLogin" time="11.489" classname="learning.lesson_19.LoginTest"/>
  <testcase name="testLogin" time="12.819" classname="learning.lesson_19.LoginTest"/>
  <testcase name="testSth" time="0.003" classname="learning.lesson_20.DataProviderExploring">
    <failure type="java.lang.AssertionError" message="The following asserts failed:
	expected [true] but found [false],
	expected [false] but found [true]">
        <![CDATA[java.lang.AssertionError: The following asserts failed:
expected [true] but found [false],
expected [false] but found [true]
at learning.lesson_20.DataProviderExploring.testSth(DataProviderExploring.java:15)
at java.util.ArrayList.forEach(Unknown Source)
at java.util.concurrent.FutureTask.run(Unknown Source)
at java.util.concurrent.ThreadPoolExecutor.runWorker(Unknown Source)
at java.util.concurrent.ThreadPoolExecutor$Worker.run(Unknown Source)
at java.lang.Thread.run(Unknown Source)
... Removed 20 stack frames]]>
    </failure>
  </testcase> <!-- testSth -->
  <testcase name="testSth" time="0.002" classname="learning.lesson_20.DataProviderExploring">
    <failure type="java.lang.AssertionError" message="The following asserts failed:
	expected [true] but found [false],
	expected [false] but found [true]">
        <![CDATA[java.lang.AssertionError: The following asserts failed:
expected [true] but found [false],
expected [false] but found [true]
at learning.lesson_20.DataProviderExploring.testSth(DataProviderExploring.java:15)
at java.util.ArrayList.forEach(Unknown Source)
at java.util.concurrent.FutureTask.run(Unknown Source)
at java.util.concurrent.ThreadPoolExecutor.runWorker(Unknown Source)
at java.util.concurrent.ThreadPoolExecutor$Worker.run(Unknown Source)
at java.lang.Thread.run(Unknown Source)
... Removed 20 stack frames]]>
    </failure>
  </testcase> <!-- testSth -->
  <testcase name="testSth" time="0.002" classname="learning.lesson_20.DataProviderExploring">
    <failure type="java.lang.AssertionError" message="The following asserts failed:
	expected [true] but found [false],
	expected [false] but found [true]">
        <![CDATA[java.lang.AssertionError: The following asserts failed:
expected [true] but found [false],
expected [false] but found [true]
at learning.lesson_20.DataProviderExploring.testSth(DataProviderExploring.java:15)
at java.util.ArrayList.forEach(Unknown Source)
at java.util.concurrent.FutureTask.run(Unknown Source)
at java.util.concurrent.ThreadPoolExecutor.runWorker(Unknown Source)
at java.util.concurrent.ThreadPoolExecutor$Worker.run(Unknown Source)
at java.lang.Thread.run(Unknown Source)
... Removed 20 stack frames]]>
    </failure>
  </testcase> <!-- testSth -->
  <testcase name="testA" time="0.002" classname="learning.lesson_20.TestNGHook01"/>
  <testcase name="testB" time="0.001" classname="learning.lesson_20.TestNGHook01"/>
  <testcase name="testA" time="0.002" classname="learning.lesson_20.TestNGHook02"/>
  <testcase name="testB" time="0.002" classname="learning.lesson_20.TestNGHook02"/>
  <testcase name="testTestNGParams" time="0.002" classname="learning.testng.ParameterTest"/>
  <testcase name="testTestNGParams" time="0.003" classname="learning.testng.ParameterTest2"/>
</testsuite> <!-- G8S1LV05133401MM -->
